//
//  WorkerThread.swift
//  ThreadSample
//
//  Created by Alessandro Marzoli on 14/06/22.
//

import Foundation

final class WorkerThread: Thread {
  convenience init(name: String, qualityOfService: QualityOfService ) {
    self.init()
    self.name = name
    self.qualityOfService = qualityOfService
  }

  override func main() {
    autoreleasepool {
      RunLoop.current.add(Port(), forMode: .default) // required or the RunLoop will exit immediatly
      RunLoop.current.run()
    }
  }

  override func cancel() {
    fatalError("\(name ?? String(describing: type(of: self))) doesn't support cancellation.")
  }
}

extension WorkerThread {
  static let shared: WorkerThread = {
    let thread = WorkerThread(name: "Shared Thread", qualityOfService: .userInitiated)
    thread.start()
    return thread
  }()
}

extension WorkerThread {
  static let timer: WorkerThread = {
    let thread = WorkerThread(name: "Timer Thread", qualityOfService: .userInitiated)
    thread.start()
    return thread
  }()
}

extension Thread {
  typealias Block = @convention(block) () -> Void

  /// Perform work on current thread asynchronously.
  /// - parameter block: Process to be executed.
  func async(execute work: @escaping Block) {
    perform(#selector(run(block:)), on: self, with: work as AnyObject, waitUntilDone: false)
  }

  /// Perform work on current thread asynchronously after a delay.
  /// - Parameters:
  ///   - delay: The minimum time after which the work is processed. Specifying a delay of 0 does not necessarily cause the work to be performed immediately.
  ///   - work: Process to be executed.
  func async(afterDelay delay: TimeInterval, execute work: @escaping Block) {
    // internally sets up a timer to perform the selector message on the current thread‚Äôs run loop.
    perform(#selector(run(block:)), with: work as AnyObject, afterDelay: delay)
  }

  /// Performs work on current thread synchronously.
  /// - parameter work: Process to be executed.
//  func sync<T>(execute work: () throws -> T) rethrows -> T {
//    guard Thread.current !== self else {
//      return try work()
//    }
//
//    return try _syncHelper(execute: work, rescue: { throw $0 }) // üö© random crash
//    //return try _syncHelper2(execute: work, rescue: { throw $0 }) // ‚ö†Ô∏è it crashes rarely but the solution is not that great
//  }

  func sync<T>(execute work: @escaping () throws -> T) rethrows -> T {
    guard Thread.current !== self else {
      return try work()
    }

<<<<<<< HEAD
    return try _syncHelper3(execute: work, rescue: { throw $0 })
=======
    //return try _syncHelper(execute: work, rescue: { throw $0 }) // üö© random crash
    //return try _syncHelper2(execute: work, rescue: { throw $0 }) // ‚úÖ it doesn't crash but the solution is not that great
    return try _syncHelper3(execute: work, rescue: { throw $0 })
  }


  // sync2 accepts an escaping work because is captured by NSObject.perform(_:on:with:waitUntilDone:)
  func sync2<T>(execute work: @escaping () throws -> T) rethrows -> T {
    guard Thread.current !== self else {
      return try work()
    }
    return try _syncHelper4(execute: work, rescue: { throw $0 })
>>>>>>> 35e1760f95ac378b391f9a5fd80415a069dd4f22
  }

  private func _syncHelper3<T>(execute work: @escaping () throws -> T, rescue: ((Swift.Error) throws -> (T))) rethrows -> T {

      var result: T?
      var error: Swift.Error?
      let task: (@convention(block) () -> Void)? = {
        do {
          result = try work()
        } catch let catchedError {
          error = catchedError
        }
      }
      perform(#selector(run(block:)), on: self, with: task, waitUntilDone: true)

      if let error = error {
        return try rescue(error)
      } else {
        return result!
      }
  }

  private func _syncHelper4<T>(execute work: @escaping () throws -> T, rescue: ((Swift.Error) throws -> (T))) rethrows -> T {
    let result = autoreleasepool {
      var result: Result<T,Swift.Error>!
      let task: (@convention(block) () -> Void)? = {
        do {
          result = .success(try work())
        } catch let error {
          result = .failure(error)
        }
      }
      perform(#selector(run(block:)), on: self, with: task, waitUntilDone: true)
      return result!
    }

    switch result {
    case .success(let value): return value
    case .failure(let error): return try rescue(error)
    }
  }

  private func _syncHelper2<T>(execute work: () throws -> T, rescue: ((Swift.Error) throws -> (T))) rethrows -> T {
    return try withoutActuallyEscaping(work) { _work in
      var result: T?
      var error: Swift.Error?
      weak var wTask: AnyObject?
      autoreleasepool {
        let task: (@convention(block) () -> Void)? = {
          do {
            result = try _work()
          } catch let catchedError {
            error = catchedError
          }
        }
        wTask = task as AnyObject
        perform(#selector(run(block:)), on: self, with: wTask, waitUntilDone: true)
      }

      while wTask != nil {
        //print("task is retained")
        Thread.sleep(forTimeInterval: 0.001)
      }
      assert(wTask == nil)

      if let error = error {
        return try rescue(error)
      } else {
        return result!
      }
    }
  }

  private func _syncHelper3<T>(execute work: () throws -> T, rescue: ((Swift.Error) throws -> (T))) rethrows -> T {
    // https://stackoverflow.com/questions/1240308/do-i-have-to-retain-an-object-before-passing-it-to-performselectorwithobjecta
    // https://stackoverflow.com/questions/11228826/performselectorwithobject-and-its-retain-behavior
    return try withoutActuallyEscaping(work) { _work in

      let result = autoreleasepool {
        var result: Result<T,Swift.Error>!
        let task: (@convention(block) () -> Void)? = {
          do {
            result = .success(try _work())
          } catch let error {
            result = .failure(error)
          }
        }
        perform(#selector(run(block:)), on: self, with: task, waitUntilDone: true)
        perform(#selector(run2(block:)), on: self, with: nil, waitUntilDone: true) // it seems that enqueuing a no-op forces the cleanup of the previous block (already executed) right away
        return result!
      }

      switch result {
      case .success(let value): return value
      case .failure(let error): return try rescue(error)
      }
    }
  }

  @objc private func run(block: Block) {
    block()
  }

  @objc private func run2(block: Block?) {
    block?()
  }
}

